INFO 2025-07-27 13:55:30,427 autoreload Watching for file changes with StatReloader
INFO 2025-07-27 13:55:30,949 basehttp "GET / HTTP/1.1" 200 459
INFO 2025-07-27 13:55:30,964 basehttp "GET /static/css/style.css HTTP/1.1" 304 0
INFO 2025-07-27 13:55:31,798 basehttp "GET / HTTP/1.1" 200 459
INFO 2025-07-27 13:56:15,532 autoreload /app/landing/views.py changed, reloading.
INFO 2025-07-27 13:56:16,690 autoreload Watching for file changes with StatReloader
INFO 2025-07-27 13:56:46,530 autoreload /app/landing/views.py changed, reloading.
INFO 2025-07-27 13:56:47,707 autoreload Watching for file changes with StatReloader
INFO 2025-07-27 13:56:47,968 basehttp "GET / HTTP/1.1" 200 459
INFO 2025-07-27 13:56:47,982 basehttp "GET /static/css/style.css HTTP/1.1" 304 0
INFO 2025-07-27 13:56:48,569 basehttp "GET / HTTP/1.1" 200 459
INFO 2025-07-27 13:56:48,988 basehttp "GET / HTTP/1.1" 200 459
INFO 2025-07-27 13:58:15,360 autoreload /app/landing/views.py changed, reloading.
INFO 2025-07-27 13:58:16,567 autoreload Watching for file changes with StatReloader
INFO 2025-07-27 13:58:18,856 autoreload /app/landing/views.py changed, reloading.
INFO 2025-07-27 13:58:19,991 autoreload Watching for file changes with StatReloader
ERROR 2025-07-27 13:58:20,185 log Internal Server Error: /
Traceback (most recent call last):
  File "/usr/local/lib/python3.10/site-packages/django/contrib/sessions/backends/base.py", line 244, in _get_session
    return self._session_cache
AttributeError: 'SessionStore' object has no attribute '_session_cache'

During handling of the above exception, another exception occurred:

Traceback (most recent call last):
  File "/usr/local/lib/python3.10/site-packages/django/db/backends/utils.py", line 105, in _execute
    return self.cursor.execute(sql, params)
  File "/usr/local/lib/python3.10/site-packages/django/db/backends/sqlite3/base.py", line 360, in execute
    return super().execute(query, params)
sqlite3.OperationalError: no such table: django_session

The above exception was the direct cause of the following exception:

Traceback (most recent call last):
  File "/usr/local/lib/python3.10/site-packages/django/core/handlers/exception.py", line 55, in inner
    response = get_response(request)
  File "/usr/local/lib/python3.10/site-packages/django/core/handlers/base.py", line 197, in _get_response
    response = wrapped_callback(request, *callback_args, **callback_kwargs)
  File "/usr/local/lib/python3.10/site-packages/django/views/generic/base.py", line 105, in view
    return self.dispatch(request, *args, **kwargs)
  File "/usr/local/lib/python3.10/site-packages/django/views/generic/base.py", line 144, in dispatch
    return handler(request, *args, **kwargs)
  File "/app/landing/views.py", line 15, in get
    f"HomePageView accessed by {request.user} from IP {self.get_client_ip(request)}",
  File "/usr/local/lib/python3.10/site-packages/django/utils/functional.py", line 251, in inner
    self._setup()
  File "/usr/local/lib/python3.10/site-packages/django/utils/functional.py", line 404, in _setup
    self._wrapped = self._setupfunc()
  File "/usr/local/lib/python3.10/site-packages/django/contrib/auth/middleware.py", line 40, in <lambda>
    request.user = SimpleLazyObject(lambda: get_user(request))
  File "/usr/local/lib/python3.10/site-packages/django/contrib/auth/middleware.py", line 20, in get_user
    request._cached_user = auth.get_user(request)
  File "/usr/local/lib/python3.10/site-packages/django/contrib/auth/__init__.py", line 304, in get_user
    user_id = _get_user_session_key(request)
  File "/usr/local/lib/python3.10/site-packages/django/contrib/auth/__init__.py", line 95, in _get_user_session_key
    return get_user_model()._meta.pk.to_python(request.session[SESSION_KEY])
  File "/usr/local/lib/python3.10/site-packages/django/contrib/sessions/backends/base.py", line 55, in __getitem__
    return self._session[key]
  File "/usr/local/lib/python3.10/site-packages/django/contrib/sessions/backends/base.py", line 249, in _get_session
    self._session_cache = self.load()
  File "/usr/local/lib/python3.10/site-packages/django/contrib/sessions/backends/db.py", line 55, in load
    s = self._get_session_from_db()
  File "/usr/local/lib/python3.10/site-packages/django/contrib/sessions/backends/db.py", line 34, in _get_session_from_db
    return self.model.objects.get(
  File "/usr/local/lib/python3.10/site-packages/django/db/models/manager.py", line 87, in manager_method
    return getattr(self.get_queryset(), name)(*args, **kwargs)
  File "/usr/local/lib/python3.10/site-packages/django/db/models/query.py", line 629, in get
    num = len(clone)
  File "/usr/local/lib/python3.10/site-packages/django/db/models/query.py", line 366, in __len__
    self._fetch_all()
  File "/usr/local/lib/python3.10/site-packages/django/db/models/query.py", line 1949, in _fetch_all
    self._result_cache = list(self._iterable_class(self))
  File "/usr/local/lib/python3.10/site-packages/django/db/models/query.py", line 91, in __iter__
    results = compiler.execute_sql(
  File "/usr/local/lib/python3.10/site-packages/django/db/models/sql/compiler.py", line 1623, in execute_sql
    cursor.execute(sql, params)
  File "/usr/local/lib/python3.10/site-packages/django/db/backends/utils.py", line 122, in execute
    return super().execute(sql, params)
  File "/usr/local/lib/python3.10/site-packages/django/db/backends/utils.py", line 79, in execute
    return self._execute_with_wrappers(
  File "/usr/local/lib/python3.10/site-packages/django/db/backends/utils.py", line 92, in _execute_with_wrappers
    return executor(sql, params, many, context)
  File "/usr/local/lib/python3.10/site-packages/django/db/backends/utils.py", line 100, in _execute
    with self.db.wrap_database_errors:
  File "/usr/local/lib/python3.10/site-packages/django/db/utils.py", line 91, in __exit__
    raise dj_exc_value.with_traceback(traceback) from exc_value
  File "/usr/local/lib/python3.10/site-packages/django/db/backends/utils.py", line 105, in _execute
    return self.cursor.execute(sql, params)
  File "/usr/local/lib/python3.10/site-packages/django/db/backends/sqlite3/base.py", line 360, in execute
    return super().execute(query, params)
django.db.utils.OperationalError: no such table: django_session
ERROR 2025-07-27 13:58:20,190 basehttp "GET / HTTP/1.1" 500 180895
ERROR 2025-07-27 13:58:21,187 log Internal Server Error: /
Traceback (most recent call last):
  File "/usr/local/lib/python3.10/site-packages/django/contrib/sessions/backends/base.py", line 244, in _get_session
    return self._session_cache
AttributeError: 'SessionStore' object has no attribute '_session_cache'

During handling of the above exception, another exception occurred:

Traceback (most recent call last):
  File "/usr/local/lib/python3.10/site-packages/django/db/backends/utils.py", line 105, in _execute
    return self.cursor.execute(sql, params)
  File "/usr/local/lib/python3.10/site-packages/django/db/backends/sqlite3/base.py", line 360, in execute
    return super().execute(query, params)
sqlite3.OperationalError: no such table: django_session

The above exception was the direct cause of the following exception:

Traceback (most recent call last):
  File "/usr/local/lib/python3.10/site-packages/django/core/handlers/exception.py", line 55, in inner
    response = get_response(request)
  File "/usr/local/lib/python3.10/site-packages/django/core/handlers/base.py", line 197, in _get_response
    response = wrapped_callback(request, *callback_args, **callback_kwargs)
  File "/usr/local/lib/python3.10/site-packages/django/views/generic/base.py", line 105, in view
    return self.dispatch(request, *args, **kwargs)
  File "/usr/local/lib/python3.10/site-packages/django/views/generic/base.py", line 144, in dispatch
    return handler(request, *args, **kwargs)
  File "/app/landing/views.py", line 15, in get
    f"HomePageView accessed by {request.user} from IP {self.get_client_ip(request)}",
  File "/usr/local/lib/python3.10/site-packages/django/utils/functional.py", line 251, in inner
    self._setup()
  File "/usr/local/lib/python3.10/site-packages/django/utils/functional.py", line 404, in _setup
    self._wrapped = self._setupfunc()
  File "/usr/local/lib/python3.10/site-packages/django/contrib/auth/middleware.py", line 40, in <lambda>
    request.user = SimpleLazyObject(lambda: get_user(request))
  File "/usr/local/lib/python3.10/site-packages/django/contrib/auth/middleware.py", line 20, in get_user
    request._cached_user = auth.get_user(request)
  File "/usr/local/lib/python3.10/site-packages/django/contrib/auth/__init__.py", line 304, in get_user
    user_id = _get_user_session_key(request)
  File "/usr/local/lib/python3.10/site-packages/django/contrib/auth/__init__.py", line 95, in _get_user_session_key
    return get_user_model()._meta.pk.to_python(request.session[SESSION_KEY])
  File "/usr/local/lib/python3.10/site-packages/django/contrib/sessions/backends/base.py", line 55, in __getitem__
    return self._session[key]
  File "/usr/local/lib/python3.10/site-packages/django/contrib/sessions/backends/base.py", line 249, in _get_session
    self._session_cache = self.load()
  File "/usr/local/lib/python3.10/site-packages/django/contrib/sessions/backends/db.py", line 55, in load
    s = self._get_session_from_db()
  File "/usr/local/lib/python3.10/site-packages/django/contrib/sessions/backends/db.py", line 34, in _get_session_from_db
    return self.model.objects.get(
  File "/usr/local/lib/python3.10/site-packages/django/db/models/manager.py", line 87, in manager_method
    return getattr(self.get_queryset(), name)(*args, **kwargs)
  File "/usr/local/lib/python3.10/site-packages/django/db/models/query.py", line 629, in get
    num = len(clone)
  File "/usr/local/lib/python3.10/site-packages/django/db/models/query.py", line 366, in __len__
    self._fetch_all()
  File "/usr/local/lib/python3.10/site-packages/django/db/models/query.py", line 1949, in _fetch_all
    self._result_cache = list(self._iterable_class(self))
  File "/usr/local/lib/python3.10/site-packages/django/db/models/query.py", line 91, in __iter__
    results = compiler.execute_sql(
  File "/usr/local/lib/python3.10/site-packages/django/db/models/sql/compiler.py", line 1623, in execute_sql
    cursor.execute(sql, params)
  File "/usr/local/lib/python3.10/site-packages/django/db/backends/utils.py", line 122, in execute
    return super().execute(sql, params)
  File "/usr/local/lib/python3.10/site-packages/django/db/backends/utils.py", line 79, in execute
    return self._execute_with_wrappers(
  File "/usr/local/lib/python3.10/site-packages/django/db/backends/utils.py", line 92, in _execute_with_wrappers
    return executor(sql, params, many, context)
  File "/usr/local/lib/python3.10/site-packages/django/db/backends/utils.py", line 100, in _execute
    with self.db.wrap_database_errors:
  File "/usr/local/lib/python3.10/site-packages/django/db/utils.py", line 91, in __exit__
    raise dj_exc_value.with_traceback(traceback) from exc_value
  File "/usr/local/lib/python3.10/site-packages/django/db/backends/utils.py", line 105, in _execute
    return self.cursor.execute(sql, params)
  File "/usr/local/lib/python3.10/site-packages/django/db/backends/sqlite3/base.py", line 360, in execute
    return super().execute(query, params)
django.db.utils.OperationalError: no such table: django_session
ERROR 2025-07-27 13:58:21,188 basehttp "GET / HTTP/1.1" 500 180897
INFO 2025-07-27 13:59:06,153 autoreload /app/landing/views.py changed, reloading.
ERROR 2025-07-27 13:59:06,274 log Internal Server Error: /
Traceback (most recent call last):
  File "/usr/local/lib/python3.10/site-packages/django/contrib/sessions/backends/base.py", line 244, in _get_session
    return self._session_cache
AttributeError: 'SessionStore' object has no attribute '_session_cache'

During handling of the above exception, another exception occurred:

Traceback (most recent call last):
  File "/usr/local/lib/python3.10/site-packages/django/db/backends/utils.py", line 105, in _execute
    return self.cursor.execute(sql, params)
  File "/usr/local/lib/python3.10/site-packages/django/db/backends/sqlite3/base.py", line 360, in execute
    return super().execute(query, params)
sqlite3.OperationalError: no such table: django_session

The above exception was the direct cause of the following exception:

Traceback (most recent call last):
  File "/usr/local/lib/python3.10/site-packages/django/core/handlers/exception.py", line 55, in inner
    response = get_response(request)
  File "/usr/local/lib/python3.10/site-packages/django/core/handlers/base.py", line 197, in _get_response
    response = wrapped_callback(request, *callback_args, **callback_kwargs)
  File "/usr/local/lib/python3.10/site-packages/django/views/generic/base.py", line 105, in view
    return self.dispatch(request, *args, **kwargs)
  File "/usr/local/lib/python3.10/site-packages/django/views/generic/base.py", line 144, in dispatch
    return handler(request, *args, **kwargs)
  File "/app/landing/views.py", line 15, in get
    f"HomePageView accessed by {request.user}",
  File "/usr/local/lib/python3.10/site-packages/django/utils/functional.py", line 251, in inner
    self._setup()
  File "/usr/local/lib/python3.10/site-packages/django/utils/functional.py", line 404, in _setup
    self._wrapped = self._setupfunc()
  File "/usr/local/lib/python3.10/site-packages/django/contrib/auth/middleware.py", line 40, in <lambda>
    request.user = SimpleLazyObject(lambda: get_user(request))
  File "/usr/local/lib/python3.10/site-packages/django/contrib/auth/middleware.py", line 20, in get_user
    request._cached_user = auth.get_user(request)
  File "/usr/local/lib/python3.10/site-packages/django/contrib/auth/__init__.py", line 304, in get_user
    user_id = _get_user_session_key(request)
  File "/usr/local/lib/python3.10/site-packages/django/contrib/auth/__init__.py", line 95, in _get_user_session_key
    return get_user_model()._meta.pk.to_python(request.session[SESSION_KEY])
  File "/usr/local/lib/python3.10/site-packages/django/contrib/sessions/backends/base.py", line 55, in __getitem__
    return self._session[key]
  File "/usr/local/lib/python3.10/site-packages/django/contrib/sessions/backends/base.py", line 249, in _get_session
    self._session_cache = self.load()
  File "/usr/local/lib/python3.10/site-packages/django/contrib/sessions/backends/db.py", line 55, in load
    s = self._get_session_from_db()
  File "/usr/local/lib/python3.10/site-packages/django/contrib/sessions/backends/db.py", line 34, in _get_session_from_db
    return self.model.objects.get(
  File "/usr/local/lib/python3.10/site-packages/django/db/models/manager.py", line 87, in manager_method
    return getattr(self.get_queryset(), name)(*args, **kwargs)
  File "/usr/local/lib/python3.10/site-packages/django/db/models/query.py", line 629, in get
    num = len(clone)
  File "/usr/local/lib/python3.10/site-packages/django/db/models/query.py", line 366, in __len__
    self._fetch_all()
  File "/usr/local/lib/python3.10/site-packages/django/db/models/query.py", line 1949, in _fetch_all
    self._result_cache = list(self._iterable_class(self))
  File "/usr/local/lib/python3.10/site-packages/django/db/models/query.py", line 91, in __iter__
    results = compiler.execute_sql(
  File "/usr/local/lib/python3.10/site-packages/django/db/models/sql/compiler.py", line 1623, in execute_sql
    cursor.execute(sql, params)
  File "/usr/local/lib/python3.10/site-packages/django/db/backends/utils.py", line 122, in execute
    return super().execute(sql, params)
  File "/usr/local/lib/python3.10/site-packages/django/db/backends/utils.py", line 79, in execute
    return self._execute_with_wrappers(
  File "/usr/local/lib/python3.10/site-packages/django/db/backends/utils.py", line 92, in _execute_with_wrappers
    return executor(sql, params, many, context)
  File "/usr/local/lib/python3.10/site-packages/django/db/backends/utils.py", line 100, in _execute
    with self.db.wrap_database_errors:
  File "/usr/local/lib/python3.10/site-packages/django/db/utils.py", line 91, in __exit__
    raise dj_exc_value.with_traceback(traceback) from exc_value
  File "/usr/local/lib/python3.10/site-packages/django/db/backends/utils.py", line 105, in _execute
    return self.cursor.execute(sql, params)
  File "/usr/local/lib/python3.10/site-packages/django/db/backends/sqlite3/base.py", line 360, in execute
    return super().execute(query, params)
django.db.utils.OperationalError: no such table: django_session
ERROR 2025-07-27 13:59:06,275 basehttp "GET / HTTP/1.1" 500 180462
ERROR 2025-07-27 13:59:06,527 log Internal Server Error: /
Traceback (most recent call last):
  File "/usr/local/lib/python3.10/site-packages/django/contrib/sessions/backends/base.py", line 244, in _get_session
    return self._session_cache
AttributeError: 'SessionStore' object has no attribute '_session_cache'

During handling of the above exception, another exception occurred:

Traceback (most recent call last):
  File "/usr/local/lib/python3.10/site-packages/django/db/backends/utils.py", line 105, in _execute
    return self.cursor.execute(sql, params)
  File "/usr/local/lib/python3.10/site-packages/django/db/backends/sqlite3/base.py", line 360, in execute
    return super().execute(query, params)
sqlite3.OperationalError: no such table: django_session

The above exception was the direct cause of the following exception:

Traceback (most recent call last):
  File "/usr/local/lib/python3.10/site-packages/django/core/handlers/exception.py", line 55, in inner
    response = get_response(request)
  File "/usr/local/lib/python3.10/site-packages/django/core/handlers/base.py", line 197, in _get_response
    response = wrapped_callback(request, *callback_args, **callback_kwargs)
  File "/usr/local/lib/python3.10/site-packages/django/views/generic/base.py", line 105, in view
    return self.dispatch(request, *args, **kwargs)
  File "/usr/local/lib/python3.10/site-packages/django/views/generic/base.py", line 144, in dispatch
    return handler(request, *args, **kwargs)
  File "/app/landing/views.py", line 15, in get
    f"HomePageView accessed by {request.user}",
  File "/usr/local/lib/python3.10/site-packages/django/utils/functional.py", line 251, in inner
    self._setup()
  File "/usr/local/lib/python3.10/site-packages/django/utils/functional.py", line 404, in _setup
    self._wrapped = self._setupfunc()
  File "/usr/local/lib/python3.10/site-packages/django/contrib/auth/middleware.py", line 40, in <lambda>
    request.user = SimpleLazyObject(lambda: get_user(request))
  File "/usr/local/lib/python3.10/site-packages/django/contrib/auth/middleware.py", line 20, in get_user
    request._cached_user = auth.get_user(request)
  File "/usr/local/lib/python3.10/site-packages/django/contrib/auth/__init__.py", line 304, in get_user
    user_id = _get_user_session_key(request)
  File "/usr/local/lib/python3.10/site-packages/django/contrib/auth/__init__.py", line 95, in _get_user_session_key
    return get_user_model()._meta.pk.to_python(request.session[SESSION_KEY])
  File "/usr/local/lib/python3.10/site-packages/django/contrib/sessions/backends/base.py", line 55, in __getitem__
    return self._session[key]
  File "/usr/local/lib/python3.10/site-packages/django/contrib/sessions/backends/base.py", line 249, in _get_session
    self._session_cache = self.load()
  File "/usr/local/lib/python3.10/site-packages/django/contrib/sessions/backends/db.py", line 55, in load
    s = self._get_session_from_db()
  File "/usr/local/lib/python3.10/site-packages/django/contrib/sessions/backends/db.py", line 34, in _get_session_from_db
    return self.model.objects.get(
  File "/usr/local/lib/python3.10/site-packages/django/db/models/manager.py", line 87, in manager_method
    return getattr(self.get_queryset(), name)(*args, **kwargs)
  File "/usr/local/lib/python3.10/site-packages/django/db/models/query.py", line 629, in get
    num = len(clone)
  File "/usr/local/lib/python3.10/site-packages/django/db/models/query.py", line 366, in __len__
    self._fetch_all()
  File "/usr/local/lib/python3.10/site-packages/django/db/models/query.py", line 1949, in _fetch_all
    self._result_cache = list(self._iterable_class(self))
  File "/usr/local/lib/python3.10/site-packages/django/db/models/query.py", line 91, in __iter__
    results = compiler.execute_sql(
  File "/usr/local/lib/python3.10/site-packages/django/db/models/sql/compiler.py", line 1623, in execute_sql
    cursor.execute(sql, params)
  File "/usr/local/lib/python3.10/site-packages/django/db/backends/utils.py", line 122, in execute
    return super().execute(sql, params)
  File "/usr/local/lib/python3.10/site-packages/django/db/backends/utils.py", line 79, in execute
    return self._execute_with_wrappers(
  File "/usr/local/lib/python3.10/site-packages/django/db/backends/utils.py", line 92, in _execute_with_wrappers
    return executor(sql, params, many, context)
  File "/usr/local/lib/python3.10/site-packages/django/db/backends/utils.py", line 100, in _execute
    with self.db.wrap_database_errors:
  File "/usr/local/lib/python3.10/site-packages/django/db/utils.py", line 91, in __exit__
    raise dj_exc_value.with_traceback(traceback) from exc_value
  File "/usr/local/lib/python3.10/site-packages/django/db/backends/utils.py", line 105, in _execute
    return self.cursor.execute(sql, params)
  File "/usr/local/lib/python3.10/site-packages/django/db/backends/sqlite3/base.py", line 360, in execute
    return super().execute(query, params)
django.db.utils.OperationalError: no such table: django_session
ERROR 2025-07-27 13:59:06,528 basehttp "GET / HTTP/1.1" 500 180462
ERROR 2025-07-27 13:59:06,829 log Internal Server Error: /
Traceback (most recent call last):
  File "/usr/local/lib/python3.10/site-packages/django/contrib/sessions/backends/base.py", line 244, in _get_session
    return self._session_cache
AttributeError: 'SessionStore' object has no attribute '_session_cache'

During handling of the above exception, another exception occurred:

Traceback (most recent call last):
  File "/usr/local/lib/python3.10/site-packages/django/db/backends/utils.py", line 105, in _execute
    return self.cursor.execute(sql, params)
  File "/usr/local/lib/python3.10/site-packages/django/db/backends/sqlite3/base.py", line 360, in execute
    return super().execute(query, params)
sqlite3.OperationalError: no such table: django_session

The above exception was the direct cause of the following exception:

Traceback (most recent call last):
  File "/usr/local/lib/python3.10/site-packages/django/core/handlers/exception.py", line 55, in inner
    response = get_response(request)
  File "/usr/local/lib/python3.10/site-packages/django/core/handlers/base.py", line 197, in _get_response
    response = wrapped_callback(request, *callback_args, **callback_kwargs)
  File "/usr/local/lib/python3.10/site-packages/django/views/generic/base.py", line 105, in view
    return self.dispatch(request, *args, **kwargs)
  File "/usr/local/lib/python3.10/site-packages/django/views/generic/base.py", line 144, in dispatch
    return handler(request, *args, **kwargs)
  File "/app/landing/views.py", line 15, in get
    f"HomePageView accessed by {request.user}",
  File "/usr/local/lib/python3.10/site-packages/django/utils/functional.py", line 251, in inner
    self._setup()
  File "/usr/local/lib/python3.10/site-packages/django/utils/functional.py", line 404, in _setup
    self._wrapped = self._setupfunc()
  File "/usr/local/lib/python3.10/site-packages/django/contrib/auth/middleware.py", line 40, in <lambda>
    request.user = SimpleLazyObject(lambda: get_user(request))
  File "/usr/local/lib/python3.10/site-packages/django/contrib/auth/middleware.py", line 20, in get_user
    request._cached_user = auth.get_user(request)
  File "/usr/local/lib/python3.10/site-packages/django/contrib/auth/__init__.py", line 304, in get_user
    user_id = _get_user_session_key(request)
  File "/usr/local/lib/python3.10/site-packages/django/contrib/auth/__init__.py", line 95, in _get_user_session_key
    return get_user_model()._meta.pk.to_python(request.session[SESSION_KEY])
  File "/usr/local/lib/python3.10/site-packages/django/contrib/sessions/backends/base.py", line 55, in __getitem__
    return self._session[key]
  File "/usr/local/lib/python3.10/site-packages/django/contrib/sessions/backends/base.py", line 249, in _get_session
    self._session_cache = self.load()
  File "/usr/local/lib/python3.10/site-packages/django/contrib/sessions/backends/db.py", line 55, in load
    s = self._get_session_from_db()
  File "/usr/local/lib/python3.10/site-packages/django/contrib/sessions/backends/db.py", line 34, in _get_session_from_db
    return self.model.objects.get(
  File "/usr/local/lib/python3.10/site-packages/django/db/models/manager.py", line 87, in manager_method
    return getattr(self.get_queryset(), name)(*args, **kwargs)
  File "/usr/local/lib/python3.10/site-packages/django/db/models/query.py", line 629, in get
    num = len(clone)
  File "/usr/local/lib/python3.10/site-packages/django/db/models/query.py", line 366, in __len__
    self._fetch_all()
  File "/usr/local/lib/python3.10/site-packages/django/db/models/query.py", line 1949, in _fetch_all
    self._result_cache = list(self._iterable_class(self))
  File "/usr/local/lib/python3.10/site-packages/django/db/models/query.py", line 91, in __iter__
    results = compiler.execute_sql(
  File "/usr/local/lib/python3.10/site-packages/django/db/models/sql/compiler.py", line 1623, in execute_sql
    cursor.execute(sql, params)
  File "/usr/local/lib/python3.10/site-packages/django/db/backends/utils.py", line 122, in execute
    return super().execute(sql, params)
  File "/usr/local/lib/python3.10/site-packages/django/db/backends/utils.py", line 79, in execute
    return self._execute_with_wrappers(
  File "/usr/local/lib/python3.10/site-packages/django/db/backends/utils.py", line 92, in _execute_with_wrappers
    return executor(sql, params, many, context)
  File "/usr/local/lib/python3.10/site-packages/django/db/backends/utils.py", line 100, in _execute
    with self.db.wrap_database_errors:
  File "/usr/local/lib/python3.10/site-packages/django/db/utils.py", line 91, in __exit__
    raise dj_exc_value.with_traceback(traceback) from exc_value
  File "/usr/local/lib/python3.10/site-packages/django/db/backends/utils.py", line 105, in _execute
    return self.cursor.execute(sql, params)
  File "/usr/local/lib/python3.10/site-packages/django/db/backends/sqlite3/base.py", line 360, in execute
    return super().execute(query, params)
django.db.utils.OperationalError: no such table: django_session
ERROR 2025-07-27 13:59:06,830 basehttp "GET / HTTP/1.1" 500 180462
INFO 2025-07-27 13:59:07,441 autoreload Watching for file changes with StatReloader
ERROR 2025-07-27 13:59:08,194 log Internal Server Error: /
Traceback (most recent call last):
  File "/usr/local/lib/python3.10/site-packages/django/contrib/sessions/backends/base.py", line 244, in _get_session
    return self._session_cache
AttributeError: 'SessionStore' object has no attribute '_session_cache'

During handling of the above exception, another exception occurred:

Traceback (most recent call last):
  File "/usr/local/lib/python3.10/site-packages/django/db/backends/utils.py", line 105, in _execute
    return self.cursor.execute(sql, params)
  File "/usr/local/lib/python3.10/site-packages/django/db/backends/sqlite3/base.py", line 360, in execute
    return super().execute(query, params)
sqlite3.OperationalError: no such table: django_session

The above exception was the direct cause of the following exception:

Traceback (most recent call last):
  File "/usr/local/lib/python3.10/site-packages/django/core/handlers/exception.py", line 55, in inner
    response = get_response(request)
  File "/usr/local/lib/python3.10/site-packages/django/core/handlers/base.py", line 197, in _get_response
    response = wrapped_callback(request, *callback_args, **callback_kwargs)
  File "/usr/local/lib/python3.10/site-packages/django/views/generic/base.py", line 105, in view
    return self.dispatch(request, *args, **kwargs)
  File "/usr/local/lib/python3.10/site-packages/django/views/generic/base.py", line 144, in dispatch
    return handler(request, *args, **kwargs)
  File "/app/landing/views.py", line 15, in get
    f"HomePageView accessed by {request.user}",
  File "/usr/local/lib/python3.10/site-packages/django/utils/functional.py", line 251, in inner
    self._setup()
  File "/usr/local/lib/python3.10/site-packages/django/utils/functional.py", line 404, in _setup
    self._wrapped = self._setupfunc()
  File "/usr/local/lib/python3.10/site-packages/django/contrib/auth/middleware.py", line 40, in <lambda>
    request.user = SimpleLazyObject(lambda: get_user(request))
  File "/usr/local/lib/python3.10/site-packages/django/contrib/auth/middleware.py", line 20, in get_user
    request._cached_user = auth.get_user(request)
  File "/usr/local/lib/python3.10/site-packages/django/contrib/auth/__init__.py", line 304, in get_user
    user_id = _get_user_session_key(request)
  File "/usr/local/lib/python3.10/site-packages/django/contrib/auth/__init__.py", line 95, in _get_user_session_key
    return get_user_model()._meta.pk.to_python(request.session[SESSION_KEY])
  File "/usr/local/lib/python3.10/site-packages/django/contrib/sessions/backends/base.py", line 55, in __getitem__
    return self._session[key]
  File "/usr/local/lib/python3.10/site-packages/django/contrib/sessions/backends/base.py", line 249, in _get_session
    self._session_cache = self.load()
  File "/usr/local/lib/python3.10/site-packages/django/contrib/sessions/backends/db.py", line 55, in load
    s = self._get_session_from_db()
  File "/usr/local/lib/python3.10/site-packages/django/contrib/sessions/backends/db.py", line 34, in _get_session_from_db
    return self.model.objects.get(
  File "/usr/local/lib/python3.10/site-packages/django/db/models/manager.py", line 87, in manager_method
    return getattr(self.get_queryset(), name)(*args, **kwargs)
  File "/usr/local/lib/python3.10/site-packages/django/db/models/query.py", line 629, in get
    num = len(clone)
  File "/usr/local/lib/python3.10/site-packages/django/db/models/query.py", line 366, in __len__
    self._fetch_all()
  File "/usr/local/lib/python3.10/site-packages/django/db/models/query.py", line 1949, in _fetch_all
    self._result_cache = list(self._iterable_class(self))
  File "/usr/local/lib/python3.10/site-packages/django/db/models/query.py", line 91, in __iter__
    results = compiler.execute_sql(
  File "/usr/local/lib/python3.10/site-packages/django/db/models/sql/compiler.py", line 1623, in execute_sql
    cursor.execute(sql, params)
  File "/usr/local/lib/python3.10/site-packages/django/db/backends/utils.py", line 122, in execute
    return super().execute(sql, params)
  File "/usr/local/lib/python3.10/site-packages/django/db/backends/utils.py", line 79, in execute
    return self._execute_with_wrappers(
  File "/usr/local/lib/python3.10/site-packages/django/db/backends/utils.py", line 92, in _execute_with_wrappers
    return executor(sql, params, many, context)
  File "/usr/local/lib/python3.10/site-packages/django/db/backends/utils.py", line 100, in _execute
    with self.db.wrap_database_errors:
  File "/usr/local/lib/python3.10/site-packages/django/db/utils.py", line 91, in __exit__
    raise dj_exc_value.with_traceback(traceback) from exc_value
  File "/usr/local/lib/python3.10/site-packages/django/db/backends/utils.py", line 105, in _execute
    return self.cursor.execute(sql, params)
  File "/usr/local/lib/python3.10/site-packages/django/db/backends/sqlite3/base.py", line 360, in execute
    return super().execute(query, params)
django.db.utils.OperationalError: no such table: django_session
ERROR 2025-07-27 13:59:08,197 basehttp "GET / HTTP/1.1" 500 180462
ERROR 2025-07-27 13:59:08,815 log Internal Server Error: /
Traceback (most recent call last):
  File "/usr/local/lib/python3.10/site-packages/django/contrib/sessions/backends/base.py", line 244, in _get_session
    return self._session_cache
AttributeError: 'SessionStore' object has no attribute '_session_cache'

During handling of the above exception, another exception occurred:

Traceback (most recent call last):
  File "/usr/local/lib/python3.10/site-packages/django/db/backends/utils.py", line 105, in _execute
    return self.cursor.execute(sql, params)
  File "/usr/local/lib/python3.10/site-packages/django/db/backends/sqlite3/base.py", line 360, in execute
    return super().execute(query, params)
sqlite3.OperationalError: no such table: django_session

The above exception was the direct cause of the following exception:

Traceback (most recent call last):
  File "/usr/local/lib/python3.10/site-packages/django/core/handlers/exception.py", line 55, in inner
    response = get_response(request)
  File "/usr/local/lib/python3.10/site-packages/django/core/handlers/base.py", line 197, in _get_response
    response = wrapped_callback(request, *callback_args, **callback_kwargs)
  File "/usr/local/lib/python3.10/site-packages/django/views/generic/base.py", line 105, in view
    return self.dispatch(request, *args, **kwargs)
  File "/usr/local/lib/python3.10/site-packages/django/views/generic/base.py", line 144, in dispatch
    return handler(request, *args, **kwargs)
  File "/app/landing/views.py", line 15, in get
    f"HomePageView accessed by {request.user}",
  File "/usr/local/lib/python3.10/site-packages/django/utils/functional.py", line 251, in inner
    self._setup()
  File "/usr/local/lib/python3.10/site-packages/django/utils/functional.py", line 404, in _setup
    self._wrapped = self._setupfunc()
  File "/usr/local/lib/python3.10/site-packages/django/contrib/auth/middleware.py", line 40, in <lambda>
    request.user = SimpleLazyObject(lambda: get_user(request))
  File "/usr/local/lib/python3.10/site-packages/django/contrib/auth/middleware.py", line 20, in get_user
    request._cached_user = auth.get_user(request)
  File "/usr/local/lib/python3.10/site-packages/django/contrib/auth/__init__.py", line 304, in get_user
    user_id = _get_user_session_key(request)
  File "/usr/local/lib/python3.10/site-packages/django/contrib/auth/__init__.py", line 95, in _get_user_session_key
    return get_user_model()._meta.pk.to_python(request.session[SESSION_KEY])
  File "/usr/local/lib/python3.10/site-packages/django/contrib/sessions/backends/base.py", line 55, in __getitem__
    return self._session[key]
  File "/usr/local/lib/python3.10/site-packages/django/contrib/sessions/backends/base.py", line 249, in _get_session
    self._session_cache = self.load()
  File "/usr/local/lib/python3.10/site-packages/django/contrib/sessions/backends/db.py", line 55, in load
    s = self._get_session_from_db()
  File "/usr/local/lib/python3.10/site-packages/django/contrib/sessions/backends/db.py", line 34, in _get_session_from_db
    return self.model.objects.get(
  File "/usr/local/lib/python3.10/site-packages/django/db/models/manager.py", line 87, in manager_method
    return getattr(self.get_queryset(), name)(*args, **kwargs)
  File "/usr/local/lib/python3.10/site-packages/django/db/models/query.py", line 629, in get
    num = len(clone)
  File "/usr/local/lib/python3.10/site-packages/django/db/models/query.py", line 366, in __len__
    self._fetch_all()
  File "/usr/local/lib/python3.10/site-packages/django/db/models/query.py", line 1949, in _fetch_all
    self._result_cache = list(self._iterable_class(self))
  File "/usr/local/lib/python3.10/site-packages/django/db/models/query.py", line 91, in __iter__
    results = compiler.execute_sql(
  File "/usr/local/lib/python3.10/site-packages/django/db/models/sql/compiler.py", line 1623, in execute_sql
    cursor.execute(sql, params)
  File "/usr/local/lib/python3.10/site-packages/django/db/backends/utils.py", line 122, in execute
    return super().execute(sql, params)
  File "/usr/local/lib/python3.10/site-packages/django/db/backends/utils.py", line 79, in execute
    return self._execute_with_wrappers(
  File "/usr/local/lib/python3.10/site-packages/django/db/backends/utils.py", line 92, in _execute_with_wrappers
    return executor(sql, params, many, context)
  File "/usr/local/lib/python3.10/site-packages/django/db/backends/utils.py", line 100, in _execute
    with self.db.wrap_database_errors:
  File "/usr/local/lib/python3.10/site-packages/django/db/utils.py", line 91, in __exit__
    raise dj_exc_value.with_traceback(traceback) from exc_value
  File "/usr/local/lib/python3.10/site-packages/django/db/backends/utils.py", line 105, in _execute
    return self.cursor.execute(sql, params)
  File "/usr/local/lib/python3.10/site-packages/django/db/backends/sqlite3/base.py", line 360, in execute
    return super().execute(query, params)
django.db.utils.OperationalError: no such table: django_session
ERROR 2025-07-27 13:59:08,817 basehttp "GET / HTTP/1.1" 500 180462
INFO 2025-07-27 14:00:23,152 autoreload Watching for file changes with StatReloader
INFO 2025-07-27 14:00:27,983 views HomePageView accessed by AnonymousUser
INFO 2025-07-27 14:00:27,989 basehttp "GET / HTTP/1.1" 200 459
INFO 2025-07-27 14:00:28,006 basehttp "GET /static/css/style.css HTTP/1.1" 304 0
INFO 2025-07-27 14:00:50,969 views HomePageView accessed by AnonymousUser
INFO 2025-07-27 14:00:50,970 basehttp "GET / HTTP/1.1" 200 459
INFO 2025-07-27 14:00:51,887 views HomePageView accessed by AnonymousUser
INFO 2025-07-27 14:00:51,888 basehttp "GET / HTTP/1.1" 200 459
INFO 2025-07-27 14:00:55,955 views HomePageView accessed by AnonymousUser
INFO 2025-07-27 14:00:55,958 basehttp "GET / HTTP/1.1" 200 459
INFO 2025-07-27 14:03:57,259 autoreload Watching for file changes with StatReloader
INFO 2025-07-27 14:04:28,398 views HomePageView accessed by AnonymousUser
INFO 2025-07-27 14:04:28,403 basehttp "GET / HTTP/1.1" 200 467
INFO 2025-07-27 14:04:28,422 basehttp "GET /static/css/style.css HTTP/1.1" 304 0
INFO 2025-07-27 14:04:32,011 views InfoPageView accessed by AnonymousUser
ERROR 2025-07-27 14:04:32,428 log Internal Server Error: /about/
Traceback (most recent call last):
  File "/usr/local/lib/python3.10/site-packages/django/core/handlers/exception.py", line 55, in inner
    response = get_response(request)
  File "/usr/local/lib/python3.10/site-packages/django/core/handlers/base.py", line 220, in _get_response
    response = response.render()
  File "/usr/local/lib/python3.10/site-packages/django/template/response.py", line 114, in render
    self.content = self.rendered_content
  File "/usr/local/lib/python3.10/site-packages/django/template/response.py", line 90, in rendered_content
    template = self.resolve_template(self.template_name)
  File "/usr/local/lib/python3.10/site-packages/django/template/response.py", line 72, in resolve_template
    return select_template(template, using=self.using)
  File "/usr/local/lib/python3.10/site-packages/django/template/loader.py", line 47, in select_template
    raise TemplateDoesNotExist(", ".join(template_name_list), chain=chain)
django.template.exceptions.TemplateDoesNotExist: info.html
ERROR 2025-07-27 14:04:32,429 basehttp "GET /about/ HTTP/1.1" 500 70968
INFO 2025-07-27 14:04:45,945 autoreload /app/landing/views.py changed, reloading.
INFO 2025-07-27 14:04:46,194 autoreload Watching for file changes with StatReloader
INFO 2025-07-27 14:04:46,831 views InfoPageView accessed by AnonymousUser
INFO 2025-07-27 14:04:46,837 basehttp "GET /about/ HTTP/1.1" 200 468
INFO 2025-07-27 14:04:47,979 views InfoPageView accessed by AnonymousUser
INFO 2025-07-27 14:04:47,983 basehttp "GET /about/ HTTP/1.1" 200 468
INFO 2025-07-27 14:04:48,525 views HomePageView accessed by AnonymousUser
INFO 2025-07-27 14:04:48,526 basehttp "GET / HTTP/1.1" 200 467
INFO 2025-07-27 14:04:49,022 views InfoPageView accessed by AnonymousUser
INFO 2025-07-27 14:04:49,023 basehttp "GET /about/ HTTP/1.1" 200 468
INFO 2025-07-27 14:04:49,431 views HomePageView accessed by AnonymousUser
INFO 2025-07-27 14:04:49,431 basehttp "GET / HTTP/1.1" 200 467
INFO 2025-07-27 14:04:49,828 views InfoPageView accessed by AnonymousUser
INFO 2025-07-27 14:04:49,829 basehttp "GET /about/ HTTP/1.1" 200 468
INFO 2025-07-27 14:04:50,310 views HomePageView accessed by AnonymousUser
INFO 2025-07-27 14:04:50,313 basehttp "GET / HTTP/1.1" 200 467
INFO 2025-07-27 14:04:50,621 views InfoPageView accessed by AnonymousUser
INFO 2025-07-27 14:04:50,623 basehttp "GET /about/ HTTP/1.1" 200 468
INFO 2025-07-27 14:04:51,025 views HomePageView accessed by AnonymousUser
INFO 2025-07-27 14:04:51,026 basehttp "GET / HTTP/1.1" 200 467
INFO 2025-07-27 14:04:51,524 views InfoPageView accessed by AnonymousUser
INFO 2025-07-27 14:04:51,527 basehttp "GET /about/ HTTP/1.1" 200 468
INFO 2025-07-27 14:05:05,671 views InfoPageView accessed by AnonymousUser
INFO 2025-07-27 14:05:05,673 basehttp "GET /about/ HTTP/1.1" 200 486
INFO 2025-07-27 14:05:06,184 views InfoPageView accessed by AnonymousUser
INFO 2025-07-27 14:05:06,185 basehttp "GET /about/ HTTP/1.1" 200 486
INFO 2025-07-27 14:05:07,850 views InfoPageView accessed by AnonymousUser
INFO 2025-07-27 14:05:07,851 basehttp "GET /about/ HTTP/1.1" 200 486
INFO 2025-07-27 14:05:08,156 views HomePageView accessed by AnonymousUser
INFO 2025-07-27 14:05:08,157 basehttp "GET / HTTP/1.1" 200 467
